<sdf version='1.7'>
  <world name='default'>
    <light name='sun' type='directional'>
      <cast_shadows>1</cast_shadows>
      <pose>0 0 10 0 -0 0</pose>
      <diffuse>0.8 0.8 0.8 1</diffuse>
      <specular>0.2 0.2 0.2 1</specular>
      <attenuation>
        <range>1000</range>
        <constant>0.9</constant>
        <linear>0.01</linear>
        <quadratic>0.001</quadratic>
      </attenuation>
      <direction>-0.5 0.1 -0.9</direction>
      <spot>
        <inner_angle>0</inner_angle>
        <outer_angle>0</outer_angle>
        <falloff>0</falloff>
      </spot>
    </light>
    <model name='ground_plane'>
      <static>1</static>
      <link name='link'>
        <collision name='collision'>
          <geometry>
            <plane>
              <normal>0 0 1</normal>
              <size>100 100</size>
            </plane>
          </geometry>
          <surface>
            <contact>
              <collide_bitmask>65535</collide_bitmask>
              <ode/>
            </contact>
            <friction>
              <ode>
                <mu>100</mu>
                <mu2>50</mu2>
              </ode>
              <torsional>
                <ode/>
              </torsional>
            </friction>
            <bounce/>
          </surface>
          <max_contacts>10</max_contacts>
        </collision>
        <visual name='visual'>
          <cast_shadows>0</cast_shadows>
          <geometry>
            <plane>
              <normal>0 0 1</normal>
              <size>100 100</size>
            </plane>
          </geometry>
          <material>
            <script>
              <uri>file://media/materials/scripts/gazebo.material</uri>
              <name>Gazebo/Grey</name>
            </script>
          </material>
        </visual>
        <self_collide>0</self_collide>
        <enable_wind>0</enable_wind>
        <kinematic>0</kinematic>
      </link>
    </model>
    <gravity>0 0 -9.8</gravity>
    <magnetic_field>6e-06 2.3e-05 -4.2e-05</magnetic_field>
    <atmosphere type='adiabatic'/>
    <physics type='ode'>
      <max_step_size>0.001</max_step_size>
      <real_time_factor>1</real_time_factor>
      <real_time_update_rate>1000</real_time_update_rate>
    </physics>
    <scene>
      <ambient>0.4 0.4 0.4 1</ambient>
      <background>0.7 0.7 0.7 1</background>
      <shadows>1</shadows>
    </scene>
    <wind/>
    <spherical_coordinates>
      <surface_model>EARTH_WGS84</surface_model>
      <latitude_deg>0</latitude_deg>
      <longitude_deg>0</longitude_deg>
      <elevation>0</elevation>
      <heading_deg>0</heading_deg>
    </spherical_coordinates>
    <model name='kr5'>
      <joint name='world-base_link-fixed' type='fixed'>
        <pose relative_to='__model__'>0 0 0 0 0 -1.5707</pose>
        <parent>world</parent>
        <child>base_link</child>
      </joint>
      <link name='base_link'>
        <pose relative_to='world-base_link-fixed'>0 0 0 0 -0 0</pose>
        <inertial>
          <pose>-0.010786 1e-06 0.122344 0 -0 0</pose>
          <mass>7.68586</mass>
          <inertia>
            <ixx>0.401388</ixx>
            <ixy>5.78879e-07</ixy>
            <ixz>-0.0931268</ixz>
            <iyy>0.442073</iyy>
            <iyz>-3.37549e-07</iyz>
            <izz>0.0779227</izz>
          </inertia>
        </inertial>
        <collision name='base_link_collision'>
          <pose>0 0 0 0 -0 0</pose>
          <geometry>
            <mesh>
              <scale>1 1 1</scale>
              <uri>/home/parallels/Desktop/ESPOL/MR/Project/catkin_ws/src/KUKA_5/kr5_description/meshes/kr5_arc/collision/base_link.stl</uri>
            </mesh>
          </geometry>
          <surface>
            <contact>
              <ode/>
            </contact>
            <friction>
              <ode/>
              <torsional>
                <ode/>
              </torsional>
            </friction>
            <bounce/>
          </surface>
          <max_contacts>10</max_contacts>
        </collision>
        <collision name='base_link_fixed_joint_lump__camera_collision_1'>
          <pose>0.5 0 2 3.14159 1.57079 3.14159</pose>
          <geometry>
            <box>
              <size>0.1 0.7 0.7</size>
            </box>
          </geometry>
          <surface>
            <contact>
              <ode/>
            </contact>
            <friction>
              <ode/>
              <torsional>
                <ode/>
              </torsional>
            </friction>
            <bounce/>
          </surface>
          <max_contacts>10</max_contacts>
        </collision>
        <visual name='base_link_visual'>
          <pose>0 0 0 0 -0 0</pose>
          <geometry>
            <mesh>
              <scale>1 1 1</scale>
              <uri>/home/parallels/Desktop/ESPOL/MR/Project/catkin_ws/src/KUKA_5/kr5_description/meshes/kr5_arc/visual/base_link.dae</uri>
            </mesh>
          </geometry>
          <material>
            <script>
              <name>Gazebo/Black</name>
              <uri>file://media/materials/scripts/gazebo.material</uri>
            </script>
          </material>
        </visual>
        <visual name='base_link_fixed_joint_lump__camera_visual_1'>
          <pose>0.5 0 2 3.14159 1.57079 3.14159</pose>
          <geometry>
            <box>
              <size>0.1 0.7 0.7</size>
            </box>
          </geometry>
        </visual>
        <gravity>0</gravity>
        <sensor name='camera1' type='depth'>
          <update_rate>20</update_rate>
          <camera>
            <horizontal_fov>1.2</horizontal_fov>
            <image>
              <width>640</width>
              <height>480</height>
              <format>R8G8B8</format>
            </image>
            <clip>
              <near>0.05</near>
              <far>30</far>
            </clip>
          </camera>
          <plugin name='camera_controller' filename='libgazebo_ros_openni_kinect.so'>
            <baseline>0.2</baseline>
            <alwaysOn>0</alwaysOn>
            <updateRate>1.0</updateRate>
            <cameraName>camera1</cameraName>
            <imageTopicName>/camera1/color/image_raw</imageTopicName>
            <cameraInfoTopicName>/camera1/color/camera_info</cameraInfoTopicName>
            <depthImageTopicName>/camera1/depth/image_raw</depthImageTopicName>
            <depthImageInfoTopicName>/camera1/depth/camera_info</depthImageInfoTopicName>
            <pointCloudTopicName>/camera1/depth/points</pointCloudTopicName>
            <frameName>camera_frame_optical</frameName>
            <pointCloudCutoff>0.5</pointCloudCutoff>
            <pointCloudCutoffMax>3.0</pointCloudCutoffMax>
            <distortionK1>0.00000001</distortionK1>
            <distortionK2>0.00000001</distortionK2>
            <distortionK3>0.00000001</distortionK3>
            <distortionT1>0.00000001</distortionT1>
            <distortionT2>0.00000001</distortionT2>
            <CxPrime>0</CxPrime>
            <Cx>0</Cx>
            <Cy>0</Cy>
            <focalLength>0</focalLength>
            <hackBaseline>0</hackBaseline>
            <robotNamespace>/</robotNamespace>
          </plugin>
          <pose>0.5 0 2 3.14159 1.57079 3.14159</pose>
        </sensor>
        <self_collide>0</self_collide>
        <enable_wind>0</enable_wind>
        <kinematic>0</kinematic>
      </link>
      <joint name='joint_a1' type='revolute'>
        <pose relative_to='base_link'>0 0 0.4 3.14159 -0 0</pose>
        <parent>base_link</parent>
        <child>link_1</child>
        <axis>
          <xyz>0 0 1</xyz>
          <limit>
            <lower>-2.70526</lower>
            <upper>2.70526</upper>
            <effort>692</effort>
            <velocity>2.68781</velocity>
          </limit>
          <dynamics>
            <damping>0</damping>
            <friction>0</friction>
            <spring_reference>0</spring_reference>
            <spring_stiffness>0</spring_stiffness>
          </dynamics>
        </axis>
      </joint>
      <link name='link_1'>
        <pose relative_to='joint_a1'>0 0 0 0 -0 0</pose>
        <inertial>
          <pose>0.035997 0.007838 -0.086497 0 -0 0</pose>
          <mass>5.77242</mass>
          <inertia>
            <ixx>0.032702</ixx>
            <ixy>-0.00189988</ixy>
            <ixz>0.00937014</ixz>
            <iyy>0.0373788</iyy>
            <iyz>-0.00197023</iyz>
            <izz>0.0348614</izz>
          </inertia>
        </inertial>
        <collision name='link_1_collision'>
          <pose>0 0 0 0 -0 0</pose>
          <geometry>
            <mesh>
              <scale>1 1 1</scale>
              <uri>/home/parallels/Desktop/ESPOL/MR/Project/catkin_ws/src/KUKA_5/kr5_description/meshes/kr5_arc/collision/link_1.stl</uri>
            </mesh>
          </geometry>
          <surface>
            <contact>
              <ode/>
            </contact>
            <friction>
              <ode/>
              <torsional>
                <ode/>
              </torsional>
            </friction>
            <bounce/>
          </surface>
          <max_contacts>10</max_contacts>
        </collision>
        <visual name='link_1_visual'>
          <pose>0 0 0 0 -0 0</pose>
          <geometry>
            <mesh>
              <scale>1 1 1</scale>
              <uri>/home/parallels/Desktop/ESPOL/MR/Project/catkin_ws/src/KUKA_5/kr5_description/meshes/kr5_arc/visual/link_1.dae</uri>
            </mesh>
          </geometry>
          <material>
            <script>
              <name>Gazebo/Orange</name>
              <uri>file://media/materials/scripts/gazebo.material</uri>
            </script>
          </material>
        </visual>
        <gravity>0</gravity>
        <self_collide>0</self_collide>
        <enable_wind>0</enable_wind>
        <kinematic>0</kinematic>
      </link>
      <joint name='joint_a2' type='revolute'>
        <pose relative_to='link_1'>0.18 0 0 1.5708 -0 0</pose>
        <parent>link_1</parent>
        <child>link_2</child>
        <axis>
          <xyz>0 0 1</xyz>
          <limit>
            <lower>-3.14159</lower>
            <upper>1.13446</upper>
            <effort>574</effort>
            <velocity>2.68781</velocity>
          </limit>
          <dynamics>
            <damping>0</damping>
            <friction>0</friction>
            <spring_reference>0</spring_reference>
            <spring_stiffness>0</spring_stiffness>
          </dynamics>
        </axis>
      </joint>
      <link name='link_2'>
        <pose relative_to='joint_a2'>0 0 0 0 -0 0</pose>
        <inertial>
          <pose>0.006102 0.040112 -0.115311 0 -0 0</pose>
          <mass>4.64975</mass>
          <inertia>
            <ixx>0.066346</ixx>
            <ixy>0.000173652</ixy>
            <ixz>0.000586191</ixz>
            <iyy>0.0704079</iyy>
            <iyz>-0.00203071</iyz>
            <izz>0.0102816</izz>
          </inertia>
        </inertial>
        <collision name='link_2_collision'>
          <pose>0 0 0 0 -0 0</pose>
          <geometry>
            <mesh>
              <scale>1 1 1</scale>
              <uri>/home/parallels/Desktop/ESPOL/MR/Project/catkin_ws/src/KUKA_5/kr5_description/meshes/kr5_arc/collision/link_2.stl</uri>
            </mesh>
          </geometry>
          <surface>
            <contact>
              <ode/>
            </contact>
            <friction>
              <ode/>
              <torsional>
                <ode/>
              </torsional>
            </friction>
            <bounce/>
          </surface>
          <max_contacts>10</max_contacts>
        </collision>
        <visual name='link_2_visual'>
          <pose>0 0 0 0 -0 0</pose>
          <geometry>
            <mesh>
              <scale>1 1 1</scale>
              <uri>/home/parallels/Desktop/ESPOL/MR/Project/catkin_ws/src/KUKA_5/kr5_description/meshes/kr5_arc/visual/link_2.dae</uri>
            </mesh>
          </geometry>
          <material>
            <script>
              <name>Gazebo/Orange</name>
              <uri>file://media/materials/scripts/gazebo.material</uri>
            </script>
          </material>
        </visual>
        <gravity>0</gravity>
        <self_collide>0</self_collide>
        <enable_wind>0</enable_wind>
        <kinematic>0</kinematic>
      </link>
      <joint name='joint_a3' type='revolute'>
        <pose relative_to='link_2'>0.6 0 0 0 -0 0</pose>
        <parent>link_2</parent>
        <child>link_3</child>
        <axis>
          <xyz>0 0 1</xyz>
          <limit>
            <lower>-0.261799</lower>
            <upper>2.75762</upper>
            <effort>242</effort>
            <velocity>3.97935</velocity>
          </limit>
          <dynamics>
            <damping>0</damping>
            <friction>0</friction>
            <spring_reference>0</spring_reference>
            <spring_stiffness>0</spring_stiffness>
          </dynamics>
        </axis>
      </joint>
      <link name='link_3'>
        <pose relative_to='joint_a3'>0 0 0 0 -0 0</pose>
        <inertial>
          <pose>0.075503 -0.046482 -0.005065 0 -0 0</pose>
          <mass>4.35934</mass>
          <inertia>
            <ixx>0.0202008</ixx>
            <ixy>5.72395e-05</ixy>
            <ixz>0.000556621</ixz>
            <iyy>0.0246797</iyy>
            <iyz>0.00069702</iyz>
            <izz>0.0178068</izz>
          </inertia>
        </inertial>
        <collision name='link_3_collision'>
          <pose>0 0 0 0 -0 0</pose>
          <geometry>
            <mesh>
              <scale>1 1 1</scale>
              <uri>/home/parallels/Desktop/ESPOL/MR/Project/catkin_ws/src/KUKA_5/kr5_description/meshes/kr5_arc/collision/link_3.stl</uri>
            </mesh>
          </geometry>
          <surface>
            <contact>
              <ode/>
            </contact>
            <friction>
              <ode/>
              <torsional>
                <ode/>
              </torsional>
            </friction>
            <bounce/>
          </surface>
          <max_contacts>10</max_contacts>
        </collision>
        <visual name='link_3_visual'>
          <pose>0 0 0 0 -0 0</pose>
          <geometry>
            <mesh>
              <scale>1 1 1</scale>
              <uri>/home/parallels/Desktop/ESPOL/MR/Project/catkin_ws/src/KUKA_5/kr5_description/meshes/kr5_arc/visual/link_3.dae</uri>
            </mesh>
          </geometry>
          <material>
            <script>
              <name>Gazebo/Orange</name>
              <uri>file://media/materials/scripts/gazebo.material</uri>
            </script>
          </material>
        </visual>
        <gravity>0</gravity>
        <self_collide>0</self_collide>
        <enable_wind>0</enable_wind>
        <kinematic>0</kinematic>
      </link>
      <joint name='joint_a4' type='revolute'>
        <pose relative_to='link_3'>0 -0.12 0 3.14159 -1.57079 3.14159</pose>
        <parent>link_3</parent>
        <child>link_4</child>
        <axis>
          <xyz>0 0 1</xyz>
          <limit>
            <lower>-6.10865</lower>
            <upper>6.10865</upper>
            <effort>58</effort>
            <velocity>5.98648</velocity>
          </limit>
          <dynamics>
            <damping>0</damping>
            <friction>0</friction>
            <spring_reference>0</spring_reference>
            <spring_stiffness>0</spring_stiffness>
          </dynamics>
        </axis>
      </joint>
      <link name='link_4'>
        <pose relative_to='joint_a4'>0 0 0 0 -0 0</pose>
        <inertial>
          <pose>0.085749 -0.001494 -0.002716 0 -0 0</pose>
          <mass>2.0681</mass>
          <inertia>
            <ixx>0.00444944</ixx>
            <ixy>-0.000424915</ixy>
            <ixz>-0.000117341</ixz>
            <iyy>0.00882693</iyy>
            <iyz>0.000136971</iyz>
            <izz>0.0101131</izz>
          </inertia>
        </inertial>
        <collision name='link_4_collision'>
          <pose>0 0 0 0 -0 0</pose>
          <geometry>
            <mesh>
              <scale>1 1 1</scale>
              <uri>/home/parallels/Desktop/ESPOL/MR/Project/catkin_ws/src/KUKA_5/kr5_description/meshes/kr5_arc/collision/link_4.stl</uri>
            </mesh>
          </geometry>
          <surface>
            <contact>
              <ode/>
            </contact>
            <friction>
              <ode/>
              <torsional>
                <ode/>
              </torsional>
            </friction>
            <bounce/>
          </surface>
          <max_contacts>10</max_contacts>
        </collision>
        <visual name='link_4_visual'>
          <pose>0 0 0 0 -0 0</pose>
          <geometry>
            <mesh>
              <scale>1 1 1</scale>
              <uri>/home/parallels/Desktop/ESPOL/MR/Project/catkin_ws/src/KUKA_5/kr5_description/meshes/kr5_arc/visual/link_4.dae</uri>
            </mesh>
          </geometry>
          <material>
            <script>
              <name>Gazebo/Orange</name>
              <uri>file://media/materials/scripts/gazebo.material</uri>
            </script>
          </material>
        </visual>
        <gravity>0</gravity>
        <self_collide>0</self_collide>
        <enable_wind>0</enable_wind>
        <kinematic>0</kinematic>
      </link>
      <joint name='joint_a5' type='revolute'>
        <pose relative_to='link_4'>0 0 -0.62 3.14159 1.57079 3.14159</pose>
        <parent>link_4</parent>
        <child>link_5</child>
        <axis>
          <xyz>0 0 1</xyz>
          <limit>
            <lower>-2.26893</lower>
            <upper>2.26893</upper>
            <effort>29</effort>
            <velocity>6.70206</velocity>
          </limit>
          <dynamics>
            <damping>0</damping>
            <friction>0</friction>
            <spring_reference>0</spring_reference>
            <spring_stiffness>0</spring_stiffness>
          </dynamics>
        </axis>
      </joint>
      <link name='link_5'>
        <pose relative_to='joint_a5'>0 0 0 0 -0 0</pose>
        <inertial>
          <pose>0 0 0 0 -0 0</pose>
          <mass>0.328309</mass>
          <inertia>
            <ixx>0.000221789</ixx>
            <ixy>-9.59629e-07</ixy>
            <ixz>1.40396e-20</ixz>
            <iyy>0.000321152</iyy>
            <iyz>-4.44974e-20</iyz>
            <izz>0.000275966</izz>
          </inertia>
        </inertial>
        <collision name='link_5_collision'>
          <pose>0 0 0 0 -0 0</pose>
          <geometry>
            <mesh>
              <scale>1 1 1</scale>
              <uri>/home/parallels/Desktop/ESPOL/MR/Project/catkin_ws/src/KUKA_5/kr5_description/meshes/kr5_arc/collision/link_5.stl</uri>
            </mesh>
          </geometry>
          <surface>
            <contact>
              <ode/>
            </contact>
            <friction>
              <ode/>
              <torsional>
                <ode/>
              </torsional>
            </friction>
            <bounce/>
          </surface>
          <max_contacts>10</max_contacts>
        </collision>
        <visual name='link_5_visual'>
          <pose>0 0 0 0 -0 0</pose>
          <geometry>
            <mesh>
              <scale>1 1 1</scale>
              <uri>/home/parallels/Desktop/ESPOL/MR/Project/catkin_ws/src/KUKA_5/kr5_description/meshes/kr5_arc/visual/link_5.dae</uri>
            </mesh>
          </geometry>
          <material>
            <script>
              <name>Gazebo/Grey</name>
              <uri>file://media/materials/scripts/gazebo.material</uri>
            </script>
          </material>
        </visual>
        <gravity>0</gravity>
        <self_collide>0</self_collide>
        <enable_wind>0</enable_wind>
        <kinematic>0</kinematic>
      </link>
      <joint name='joint_a6' type='revolute'>
        <pose relative_to='link_5'>0 0 0 3.14159 -1.57079 3.14159</pose>
        <parent>link_5</parent>
        <child>link_6</child>
        <axis>
          <xyz>0 0 1</xyz>
          <limit>
            <lower>-6.10865</lower>
            <upper>6.10865</upper>
            <effort>29</effort>
            <velocity>12.5838</velocity>
          </limit>
          <dynamics>
            <damping>0</damping>
            <friction>0</friction>
            <spring_reference>0</spring_reference>
            <spring_stiffness>0</spring_stiffness>
          </dynamics>
        </axis>
      </joint>
      <link name='link_6'>
        <pose relative_to='joint_a6'>0 0 0 0 -0 0</pose>
        <inertial>
          <pose>0.001913 -5e-06 -0.113908 0 -0 0</pose>
          <mass>0.405469</mass>
          <inertia>
            <ixx>0.0316107</ixx>
            <ixy>-1.52971e-08</ixy>
            <ixz>-8.84944e-05</ixz>
            <iyy>0.0316263</iyy>
            <iyz>2.51422e-07</iyz>
            <izz>0.0301638</izz>
          </inertia>
        </inertial>
        <collision name='link_6_collision'>
          <pose>0 0 0 0 -0 0</pose>
          <geometry>
            <mesh>
              <scale>1 1 1</scale>
              <uri>/home/parallels/Desktop/ESPOL/MR/Project/catkin_ws/src/KUKA_5/kr5_description/meshes/kr5_arc/collision/link_6.stl</uri>
            </mesh>
          </geometry>
          <surface>
            <contact>
              <ode/>
            </contact>
            <friction>
              <ode/>
              <torsional>
                <ode/>
              </torsional>
            </friction>
            <bounce/>
          </surface>
          <max_contacts>10</max_contacts>
        </collision>
        <collision name='link_6_fixed_joint_lump__coupling_link_collision_1'>
          <pose>-0 0 -0.112 -3.14159 -0 1.5708</pose>
          <geometry>
            <mesh>
              <scale>0.001 0.001 0.001</scale>
              <uri>/home/parallels/Desktop/ESPOL/MR/Project/catkin_ws/src/Robotiq-grippers/robotiq_2f_85_description/meshes/visual/robotiq_gripper_coupling.stl</uri>
            </mesh>
          </geometry>
          <max_contacts>10</max_contacts>
          <surface>
            <contact>
              <ode/>
            </contact>
            <bounce/>
            <friction>
              <torsional>
                <ode/>
              </torsional>
              <ode/>
            </friction>
          </surface>
        </collision>
        <collision name='link_6_fixed_joint_lump__robotiq_arg2f_base_link_collision_2'>
          <pose>0 -0 -0.123 -3.14159 -0 1.5708</pose>
          <geometry>
            <mesh>
              <scale>1 1 1</scale>
              <uri>/home/parallels/Desktop/ESPOL/MR/Project/catkin_ws/src/Robotiq-grippers/robotiq_2f_85_description/meshes/collision/robotiq_arg2f_base_link.stl</uri>
            </mesh>
          </geometry>
          <max_contacts>10</max_contacts>
          <surface>
            <contact>
              <ode/>
            </contact>
            <bounce/>
            <friction>
              <torsional>
                <ode/>
              </torsional>
              <ode/>
            </friction>
          </surface>
        </collision>
        <visual name='link_6_visual'>
          <pose>0 0 0 0 -0 0</pose>
          <geometry>
            <mesh>
              <scale>1 1 1</scale>
              <uri>/home/parallels/Desktop/ESPOL/MR/Project/catkin_ws/src/KUKA_5/kr5_description/meshes/kr5_arc/visual/link_6.dae</uri>
            </mesh>
          </geometry>
          <material>
            <script>
              <name>Gazebo/Grey</name>
              <uri>file://media/materials/scripts/gazebo.material</uri>
            </script>
          </material>
        </visual>
        <visual name='link_6_fixed_joint_lump__coupling_link_visual_1'>
          <pose>0 -0 -0.119 3.14159 -0 0</pose>
          <geometry>
            <mesh>
              <scale>0.001 0.001 0.001</scale>
              <uri>/home/parallels/Desktop/ESPOL/MR/Project/catkin_ws/src/Robotiq-grippers/robotiq_2f_85_description/meshes/visual/robotiq_gripper_coupling.stl</uri>
            </mesh>
          </geometry>
        </visual>
        <visual name='link_6_fixed_joint_lump__robotiq_arg2f_base_link_visual_2'>
          <pose>0 -0 -0.123 -3.14159 -0 1.5708</pose>
          <geometry>
            <mesh>
              <scale>1 1 1</scale>
              <uri>/home/parallels/Desktop/ESPOL/MR/Project/catkin_ws/src/Robotiq-grippers/robotiq_2f_85_description/meshes/collision/robotiq_arg2f_base_link.stl</uri>
            </mesh>
          </geometry>
        </visual>
        <gravity>0</gravity>
        <self_collide>0</self_collide>
        <enable_wind>0</enable_wind>
        <kinematic>0</kinematic>
      </link>
      <joint name='finger_joint' type='revolute'>
        <pose relative_to='link_6'>-0.030601 -0 -0.177904 -3.14159 0 -1.5708</pose>
        <parent>link_6</parent>
        <child>left_outer_knuckle</child>
        <axis>
          <xyz>1 0 0</xyz>
          <limit>
            <lower>0</lower>
            <upper>0.8</upper>
            <effort>1000</effort>
            <velocity>2</velocity>
          </limit>
          <dynamics>
            <spring_reference>0</spring_reference>
            <spring_stiffness>0</spring_stiffness>
          </dynamics>
        </axis>
      </joint>
      <link name='left_outer_knuckle'>
        <pose relative_to='finger_joint'>0 0 0 0 -0 0</pose>
        <inertial>
          <pose>0 0.01575 -0.00205 0 -0 0</pose>
          <mass>0.2</mass>
          <inertia>
            <ixx>0.0600505</ixx>
            <ixy>0</ixy>
            <ixz>0</ixz>
            <iyy>0.0600008</iyy>
            <iyz>6.4575e-06</iyz>
            <izz>0.0600496</izz>
          </inertia>
        </inertial>
        <collision name='left_outer_knuckle_collision'>
          <pose>0 0 0 0 -0 0</pose>
          <geometry>
            <mesh>
              <scale>0.001 0.001 0.001</scale>
              <uri>/home/parallels/Desktop/ESPOL/MR/Project/catkin_ws/src/Robotiq-grippers/robotiq_2f_85_description/meshes/collision/robotiq_arg2f_85_outer_knuckle.dae</uri>
            </mesh>
          </geometry>
          <max_contacts>10</max_contacts>
          <surface>
            <contact>
              <ode/>
            </contact>
            <bounce/>
            <friction>
              <torsional>
                <ode/>
              </torsional>
              <ode/>
            </friction>
          </surface>
        </collision>
        <collision name='left_outer_knuckle_fixed_joint_lump__left_outer_finger_collision_1'>
          <pose>0 0.0315 -0.0041 0 -0 0</pose>
          <geometry>
            <mesh>
              <scale>0.001 0.001 0.001</scale>
              <uri>/home/parallels/Desktop/ESPOL/MR/Project/catkin_ws/src/Robotiq-grippers/robotiq_2f_85_description/meshes/collision/robotiq_arg2f_85_outer_finger.dae</uri>
            </mesh>
          </geometry>
          <max_contacts>10</max_contacts>
          <surface>
            <contact>
              <ode/>
            </contact>
            <bounce/>
            <friction>
              <torsional>
                <ode/>
              </torsional>
              <ode/>
            </friction>
          </surface>
        </collision>
        <visual name='left_outer_knuckle_visual'>
          <pose>0 0 0 0 -0 0</pose>
          <geometry>
            <mesh>
              <scale>0.001 0.001 0.001</scale>
              <uri>/home/parallels/Desktop/ESPOL/MR/Project/catkin_ws/src/Robotiq-grippers/robotiq_2f_85_description/meshes/visual/robotiq_arg2f_85_outer_knuckle.dae</uri>
            </mesh>
          </geometry>
        </visual>
        <visual name='left_outer_knuckle_fixed_joint_lump__left_outer_finger_visual_1'>
          <pose>0 0.0315 -0.0041 0 -0 0</pose>
          <geometry>
            <mesh>
              <scale>0.001 0.001 0.001</scale>
              <uri>/home/parallels/Desktop/ESPOL/MR/Project/catkin_ws/src/Robotiq-grippers/robotiq_2f_85_description/meshes/visual/robotiq_arg2f_85_outer_finger.dae</uri>
            </mesh>
          </geometry>
        </visual>
        <self_collide>0</self_collide>
        <enable_wind>0</enable_wind>
        <kinematic>0</kinematic>
      </link>
      <joint name='left_inner_finger_joint' type='revolute'>
        <pose relative_to='left_outer_knuckle'>0 0.0376 0.043 0 -0 0</pose>
        <parent>left_outer_knuckle</parent>
        <child>left_inner_finger</child>
        <axis>
          <xyz>1 0 0</xyz>
          <limit>
            <lower>-0.8757</lower>
            <upper>0.8757</upper>
            <effort>1000</effort>
            <velocity>2</velocity>
          </limit>
          <dynamics>
            <spring_reference>0</spring_reference>
            <spring_stiffness>0</spring_stiffness>
          </dynamics>
        </axis>
      </joint>
      <link name='left_inner_finger'>
        <pose relative_to='left_inner_finger_joint'>0 0 0 0 -0 0</pose>
        <inertial>
          <pose>0 -0.01101 0.01621 0 -0 0</pose>
          <mass>0.2</mass>
          <inertia>
            <ixx>0.0600768</ixx>
            <ixy>0</ixy>
            <ixz>0</ixz>
            <iyy>0.0600526</iyy>
            <iyz>3.5695e-05</iyz>
            <izz>0.0600242</izz>
          </inertia>
        </inertial>
        <collision name='left_inner_finger_collision'>
          <pose>0 0 0 0 -0 0</pose>
          <geometry>
            <mesh>
              <scale>0.001 0.001 0.001</scale>
              <uri>/home/parallels/Desktop/ESPOL/MR/Project/catkin_ws/src/Robotiq-grippers/robotiq_2f_85_description/meshes/collision/robotiq_arg2f_85_inner_finger.dae</uri>
            </mesh>
          </geometry>
          <max_contacts>10</max_contacts>
          <surface>
            <contact>
              <ode/>
            </contact>
            <bounce/>
            <friction>
              <torsional>
                <ode/>
              </torsional>
              <ode/>
            </friction>
          </surface>
        </collision>
        <collision name='left_inner_finger_pad_collision_1'>
          <pose>0 -0.02202 0.03242 0 -0 0</pose>
          <geometry>
            <box>
              <size>0.022 0.00635 0.0375</size>
            </box>
          </geometry>
          <max_contacts>10</max_contacts>
          <surface>
            <contact>
              <ode/>
            </contact>
            <bounce/>
            <friction>
              <torsional>
                <ode/>
              </torsional>
              <ode/>
            </friction>
          </surface>
        </collision>
        <visual name='left_inner_finger_visual'>
          <pose>0 0 0 0 -0 0</pose>
          <geometry>
            <mesh>
              <scale>0.001 0.001 0.001</scale>
              <uri>/home/parallels/Desktop/ESPOL/MR/Project/catkin_ws/src/Robotiq-grippers/robotiq_2f_85_description/meshes/visual/robotiq_arg2f_85_inner_finger.dae</uri>
            </mesh>
          </geometry>
        </visual>
        <visual name='left_inner_finger_pad_visual_1'>
          <pose>0 -0.02202 0.03242 0 -0 0</pose>
          <geometry>
            <box>
              <size>0.022 0.00635 0.0375</size>
            </box>
          </geometry>
        </visual>
        <self_collide>0</self_collide>
        <enable_wind>0</enable_wind>
        <kinematic>0</kinematic>
      </link>
      <joint name='left_inner_knuckle_joint' type='revolute'>
        <pose relative_to='link_6'>-0.0127 -0 -0.18442 -3.14159 0 -1.5708</pose>
        <parent>link_6</parent>
        <child>left_inner_knuckle</child>
        <axis>
          <xyz>1 0 0</xyz>
          <limit>
            <lower>0</lower>
            <upper>0.8757</upper>
            <effort>1000</effort>
            <velocity>2</velocity>
          </limit>
          <dynamics>
            <spring_reference>0</spring_reference>
            <spring_stiffness>0</spring_stiffness>
          </dynamics>
        </axis>
      </joint>
      <link name='left_inner_knuckle'>
        <pose relative_to='left_inner_knuckle_joint'>0 0 0 0 -0 0</pose>
        <inertial>
          <pose>0 0 0 0 -0 0</pose>
          <mass>0.1</mass>
          <inertia>
            <ixx>0.03</ixx>
            <ixy>0</ixy>
            <ixz>0</ixz>
            <iyy>0.03</iyy>
            <iyz>0</iyz>
            <izz>0.03</izz>
          </inertia>
        </inertial>
        <collision name='left_inner_knuckle_collision'>
          <pose>0 0 0 0 -0 0</pose>
          <geometry>
            <mesh>
              <scale>0.001 0.001 0.001</scale>
              <uri>/home/parallels/Desktop/ESPOL/MR/Project/catkin_ws/src/Robotiq-grippers/robotiq_2f_85_description/meshes/collision/robotiq_arg2f_85_inner_knuckle.dae</uri>
            </mesh>
          </geometry>
          <max_contacts>10</max_contacts>
          <surface>
            <contact>
              <ode/>
            </contact>
            <bounce/>
            <friction>
              <torsional>
                <ode/>
              </torsional>
              <ode/>
            </friction>
          </surface>
        </collision>
        <visual name='left_inner_knuckle_visual'>
          <pose>0 0 0 0 -0 0</pose>
          <geometry>
            <mesh>
              <scale>0.001 0.001 0.001</scale>
              <uri>/home/parallels/Desktop/ESPOL/MR/Project/catkin_ws/src/Robotiq-grippers/robotiq_2f_85_description/meshes/visual/robotiq_arg2f_85_inner_knuckle.dae</uri>
            </mesh>
          </geometry>
        </visual>
        <self_collide>0</self_collide>
        <enable_wind>0</enable_wind>
        <kinematic>0</kinematic>
      </link>
      <joint name='right_inner_knuckle_joint' type='revolute'>
        <pose relative_to='link_6'>0.0127 -0 -0.18442 -3.14159 -0 1.5708</pose>
        <parent>link_6</parent>
        <child>right_inner_knuckle</child>
        <axis>
          <xyz>1 0 0</xyz>
          <limit>
            <lower>0</lower>
            <upper>0.8757</upper>
            <effort>1000</effort>
            <velocity>2</velocity>
          </limit>
          <dynamics>
            <spring_reference>0</spring_reference>
            <spring_stiffness>0</spring_stiffness>
          </dynamics>
        </axis>
      </joint>
      <link name='right_inner_knuckle'>
        <pose relative_to='right_inner_knuckle_joint'>0 0 0 0 -0 0</pose>
        <inertial>
          <pose>0 0 0 0 -0 0</pose>
          <mass>0.1</mass>
          <inertia>
            <ixx>0.03</ixx>
            <ixy>0</ixy>
            <ixz>0</ixz>
            <iyy>0.03</iyy>
            <iyz>0</iyz>
            <izz>0.03</izz>
          </inertia>
        </inertial>
        <collision name='right_inner_knuckle_collision'>
          <pose>0 0 0 0 -0 0</pose>
          <geometry>
            <mesh>
              <scale>0.001 0.001 0.001</scale>
              <uri>/home/parallels/Desktop/ESPOL/MR/Project/catkin_ws/src/Robotiq-grippers/robotiq_2f_85_description/meshes/collision/robotiq_arg2f_85_inner_knuckle.dae</uri>
            </mesh>
          </geometry>
          <max_contacts>10</max_contacts>
          <surface>
            <contact>
              <ode/>
            </contact>
            <bounce/>
            <friction>
              <torsional>
                <ode/>
              </torsional>
              <ode/>
            </friction>
          </surface>
        </collision>
        <visual name='right_inner_knuckle_visual'>
          <pose>0 0 0 0 -0 0</pose>
          <geometry>
            <mesh>
              <scale>0.001 0.001 0.001</scale>
              <uri>/home/parallels/Desktop/ESPOL/MR/Project/catkin_ws/src/Robotiq-grippers/robotiq_2f_85_description/meshes/visual/robotiq_arg2f_85_inner_knuckle.dae</uri>
            </mesh>
          </geometry>
        </visual>
        <self_collide>0</self_collide>
        <enable_wind>0</enable_wind>
        <kinematic>0</kinematic>
      </link>
      <joint name='right_outer_knuckle_joint' type='revolute'>
        <pose relative_to='link_6'>0.030601 -0 -0.177904 -3.14159 -0 1.5708</pose>
        <parent>link_6</parent>
        <child>right_outer_knuckle</child>
        <axis>
          <xyz>1 0 0</xyz>
          <limit>
            <lower>0</lower>
            <upper>0.81</upper>
            <effort>1000</effort>
            <velocity>2</velocity>
          </limit>
          <dynamics>
            <spring_reference>0</spring_reference>
            <spring_stiffness>0</spring_stiffness>
          </dynamics>
        </axis>
      </joint>
      <link name='right_outer_knuckle'>
        <pose relative_to='right_outer_knuckle_joint'>0 0 0 0 -0 0</pose>
        <inertial>
          <pose>0 0.01575 -0.00205 0 -0 0</pose>
          <mass>0.2</mass>
          <inertia>
            <ixx>0.0600505</ixx>
            <ixy>0</ixy>
            <ixz>0</ixz>
            <iyy>0.0600008</iyy>
            <iyz>6.4575e-06</iyz>
            <izz>0.0600496</izz>
          </inertia>
        </inertial>
        <collision name='right_outer_knuckle_collision'>
          <pose>0 0 0 0 -0 0</pose>
          <geometry>
            <mesh>
              <scale>0.001 0.001 0.001</scale>
              <uri>/home/parallels/Desktop/ESPOL/MR/Project/catkin_ws/src/Robotiq-grippers/robotiq_2f_85_description/meshes/collision/robotiq_arg2f_85_outer_knuckle.dae</uri>
            </mesh>
          </geometry>
          <max_contacts>10</max_contacts>
          <surface>
            <contact>
              <ode/>
            </contact>
            <bounce/>
            <friction>
              <torsional>
                <ode/>
              </torsional>
              <ode/>
            </friction>
          </surface>
        </collision>
        <collision name='right_outer_knuckle_fixed_joint_lump__right_outer_finger_collision_1'>
          <pose>0 0.0315 -0.0041 0 -0 0</pose>
          <geometry>
            <mesh>
              <scale>0.001 0.001 0.001</scale>
              <uri>/home/parallels/Desktop/ESPOL/MR/Project/catkin_ws/src/Robotiq-grippers/robotiq_2f_85_description/meshes/collision/robotiq_arg2f_85_outer_finger.dae</uri>
            </mesh>
          </geometry>
          <max_contacts>10</max_contacts>
          <surface>
            <contact>
              <ode/>
            </contact>
            <bounce/>
            <friction>
              <torsional>
                <ode/>
              </torsional>
              <ode/>
            </friction>
          </surface>
        </collision>
        <visual name='right_outer_knuckle_visual'>
          <pose>0 0 0 0 -0 0</pose>
          <geometry>
            <mesh>
              <scale>0.001 0.001 0.001</scale>
              <uri>/home/parallels/Desktop/ESPOL/MR/Project/catkin_ws/src/Robotiq-grippers/robotiq_2f_85_description/meshes/visual/robotiq_arg2f_85_outer_knuckle.dae</uri>
            </mesh>
          </geometry>
        </visual>
        <visual name='right_outer_knuckle_fixed_joint_lump__right_outer_finger_visual_1'>
          <pose>0 0.0315 -0.0041 0 -0 0</pose>
          <geometry>
            <mesh>
              <scale>0.001 0.001 0.001</scale>
              <uri>/home/parallels/Desktop/ESPOL/MR/Project/catkin_ws/src/Robotiq-grippers/robotiq_2f_85_description/meshes/visual/robotiq_arg2f_85_outer_finger.dae</uri>
            </mesh>
          </geometry>
        </visual>
        <self_collide>0</self_collide>
        <enable_wind>0</enable_wind>
        <kinematic>0</kinematic>
      </link>
      <joint name='right_inner_finger_joint' type='revolute'>
        <pose relative_to='right_outer_knuckle'>0 0.0376 0.043 0 -0 0</pose>
        <parent>right_outer_knuckle</parent>
        <child>right_inner_finger</child>
        <axis>
          <xyz>1 0 0</xyz>
          <limit>
            <lower>-0.8757</lower>
            <upper>0.8757</upper>
            <effort>1000</effort>
            <velocity>2</velocity>
          </limit>
          <dynamics>
            <spring_reference>0</spring_reference>
            <spring_stiffness>0</spring_stiffness>
          </dynamics>
        </axis>
      </joint>
      <link name='right_inner_finger'>
        <pose relative_to='right_inner_finger_joint'>0 0 0 0 -0 0</pose>
        <inertial>
          <pose>0 -0.01101 0.01621 0 -0 0</pose>
          <mass>0.2</mass>
          <inertia>
            <ixx>0.0600768</ixx>
            <ixy>0</ixy>
            <ixz>0</ixz>
            <iyy>0.0600526</iyy>
            <iyz>3.5695e-05</iyz>
            <izz>0.0600242</izz>
          </inertia>
        </inertial>
        <collision name='right_inner_finger_collision'>
          <pose>0 0 0 0 -0 0</pose>
          <geometry>
            <mesh>
              <scale>0.001 0.001 0.001</scale>
              <uri>/home/parallels/Desktop/ESPOL/MR/Project/catkin_ws/src/Robotiq-grippers/robotiq_2f_85_description/meshes/collision/robotiq_arg2f_85_inner_finger.dae</uri>
            </mesh>
          </geometry>
          <max_contacts>10</max_contacts>
          <surface>
            <contact>
              <ode/>
            </contact>
            <bounce/>
            <friction>
              <torsional>
                <ode/>
              </torsional>
              <ode/>
            </friction>
          </surface>
        </collision>
        <collision name='right_inner_finger_pad_collision_1'>
          <pose>0 -0.02202 0.03242 0 -0 0</pose>
          <geometry>
            <box>
              <size>0.022 0.00635 0.0375</size>
            </box>
          </geometry>
          <max_contacts>10</max_contacts>
          <surface>
            <contact>
              <ode/>
            </contact>
            <bounce/>
            <friction>
              <torsional>
                <ode/>
              </torsional>
              <ode/>
            </friction>
          </surface>
        </collision>
        <visual name='right_inner_finger_visual'>
          <pose>0 0 0 0 -0 0</pose>
          <geometry>
            <mesh>
              <scale>0.001 0.001 0.001</scale>
              <uri>/home/parallels/Desktop/ESPOL/MR/Project/catkin_ws/src/Robotiq-grippers/robotiq_2f_85_description/meshes/visual/robotiq_arg2f_85_inner_finger.dae</uri>
            </mesh>
          </geometry>
        </visual>
        <visual name='right_inner_finger_pad_visual_1'>
          <pose>0 -0.02202 0.03242 0 -0 0</pose>
          <geometry>
            <box>
              <size>0.022 0.00635 0.0375</size>
            </box>
          </geometry>
        </visual>
        <self_collide>0</self_collide>
        <enable_wind>0</enable_wind>
        <kinematic>0</kinematic>
      </link>
      <plugin name='gazebo_ros_control' filename='libgazebo_ros_control.so'>
        <robotNamespace>/</robotNamespace>
        <robotSimType>gazebo_ros_control/DefaultRobotHWSim</robotSimType>
      </plugin>
      <plugin name='mimic_robotiq_85_1' filename='libroboticsgroup_upatras_gazebo_mimic_joint_plugin.so'>
        <joint>finger_joint</joint>
        <mimicJoint>right_outer_knuckle_joint</mimicJoint>
        <multiplier>1.0</multiplier>
        <robotNamespace>/</robotNamespace>
      </plugin>
      <plugin name='mimic_robotiq_85_5' filename='libroboticsgroup_upatras_gazebo_mimic_joint_plugin.so'>
        <joint>finger_joint</joint>
        <mimicJoint>left_inner_finger_joint</mimicJoint>
        <multiplier>-1.0</multiplier>
        <robotNamespace>/</robotNamespace>
      </plugin>
      <plugin name='mimic_robotiq_85_4' filename='libroboticsgroup_upatras_gazebo_mimic_joint_plugin.so'>
        <joint>finger_joint</joint>
        <mimicJoint>right_inner_finger_joint</mimicJoint>
        <multiplier>-1.0</multiplier>
        <robotNamespace>/</robotNamespace>
      </plugin>
      <plugin name='mimic_robotiq_85_2' filename='libroboticsgroup_upatras_gazebo_mimic_joint_plugin.so'>
        <joint>finger_joint</joint>
        <mimicJoint>left_inner_knuckle_joint</mimicJoint>
        <multiplier>1.0</multiplier>
        <robotNamespace>/</robotNamespace>
      </plugin>
      <plugin name='mimic_robotiq_85_3' filename='libroboticsgroup_upatras_gazebo_mimic_joint_plugin.so'>
        <joint>finger_joint</joint>
        <mimicJoint>right_inner_knuckle_joint</mimicJoint>
        <multiplier>1.0</multiplier>
        <robotNamespace>/</robotNamespace>
      </plugin>
      <static>0</static>
      <plugin name='gazebo_grasp_fix' filename='libgazebo_grasp_fix.so'>
        <arm>
          <arm_name>kuka_kr5</arm_name>
          <palm_link>link_6</palm_link>
          <gripper_link>left_outer_knuckle</gripper_link>
          <gripper_link>right_outer_knuckle</gripper_link>
          <gripper_link>left_inner_finger</gripper_link>
          <gripper_link>right_inner_finger</gripper_link>
        </arm>
        <forces_angle_tolerance>90</forces_angle_tolerance>
        <update_rate>4</update_rate>
        <grip_count_threshold>4</grip_count_threshold>
        <max_grip_count>8</max_grip_count>
        <release_tolerance>0.005</release_tolerance>
        <disable_collisions_on_attach>0</disable_collisions_on_attach>
        <contact_topic>__default_topic__</contact_topic>
        <robotNamespace>/</robotNamespace>
      </plugin>
      <pose>0 0 0 0 -0 0</pose>
    </model>
    <state world_name='default'>
      <sim_time>612 113000000</sim_time>
      <real_time>622 254672472</real_time>
      <wall_time>1692493925 826936470</wall_time>
      <iterations>612113</iterations>
      <model name='blue_table'>
        <pose>1.00143 0.003949 0 0 -0 0</pose>
        <scale>1 1 1</scale>
        <link name='link'>
          <pose>1.00143 0.003949 0 0 -0 0</pose>
          <velocity>0 0 0 0 -0 0</velocity>
          <acceleration>0 0 0 0 -0 0</acceleration>
          <wrench>0 0 0 0 -0 0</wrench>
        </link>
      </model>
      <model name='ground_plane'>
        <pose>0 0 0 0 -0 0</pose>
        <scale>1 1 1</scale>
        <link name='link'>
          <pose>0 0 0 0 -0 0</pose>
          <velocity>0 0 0 0 -0 0</velocity>
          <acceleration>0 0 0 0 -0 0</acceleration>
          <wrench>0 0 0 0 -0 0</wrench>
        </link>
      </model>
      <model name='kr5'>
        <pose>-0 -0 0 0 -0 0</pose>
        <scale>1 1 1</scale>
        <link name='base_link'>
          <pose>-0 -0 0 -0 -0 -1.5707</pose>
          <velocity>0 -1e-06 6e-06 -1.6e-05 -1.5e-05 4e-06</velocity>
          <acceleration>-0.003272 -0.000589 0.012357 -0.019618 -0.067987 0.117463</acceleration>
          <wrench>-0.025149 -0.004524 0.094974 0 -0 0</wrench>
        </link>
        <link name='left_inner_finger'>
          <pose>-1.05566 -0.066966 0.959629 -3.12173 -0.072159 -0.047912</pose>
          <velocity>0.001996 -0.000444 -0.003208 7.5e-05 -0.016777 8.2e-05</velocity>
          <acceleration>-0.001318 0.000297 -0.001342 1.7e-05 -0.000864 0.000229</acceleration>
          <wrench>-0.000264 5.9e-05 -0.000268 0 -0 0</wrench>
        </link>
        <link name='left_inner_knuckle'>
          <pose>-1.05574 -0.012134 0.997111 -3.12173 -0.072159 -0.047912</pose>
          <velocity>0.001363 -0.000447 -0.003206 4.8e-05 -0.016776 8e-05</velocity>
          <acceleration>-0.001562 0.0002 -0.001149 -0.00016 -0.001163 0.000187</acceleration>
          <wrench>-0.000156 2e-05 -0.000115 0 -0 0</wrench>
        </link>
        <link name='left_outer_knuckle'>
          <pose>-1.05705 -0.030118 1.00325 -3.12173 -0.072159 -0.047912</pose>
          <velocity>0.001261 -0.000447 -0.003229 7.4e-05 -0.016777 8.2e-05</velocity>
          <acceleration>-0.001298 0.000332 -0.001425 1.7e-05 -0.000801 0.000217</acceleration>
          <wrench>-0.00026 6.6e-05 -0.000285 0 -0 0</wrench>
        </link>
        <link name='link_1'>
          <pose>-1e-06 -0 0.4 3.14159 -5e-06 -3.13928</pose>
          <velocity>-5e-06 4e-06 6e-06 -1.8e-05 -1.9e-05 0.00044</velocity>
          <acceleration>-0.016823 0.005826 0.011015 -0.016228 -0.052164 0.037561</acceleration>
          <wrench>-0.097109 0.033633 0.063584 0 -0 0</wrench>
        </link>
        <link name='link_2'>
          <pose>-0.18 -0.000416 0.399999 -1.57079 -1.00961 -3.13929</pose>
          <velocity>-6e-06 -7.5e-05 3e-06 -1.5e-05 -0.000268 0.000441</velocity>
          <acceleration>-0.015056 -0.001691 1.8e-05 -0.031471 -0.4047 -0.002946</acceleration>
          <wrench>-0.070005 -0.007862 8.3e-05 0 -0 0</wrench>
        </link>
        <link name='link_3'>
          <pose>-0.499314 -0.001153 0.90797 -1.57079 -0.25642 -3.13928</pose>
          <velocity>-0.000126 -0.000211 -7.5e-05 1e-06 -0.005869 0.000444</velocity>
          <acceleration>-0.00583 0.003501 0.007625 -0.026548 0.007089 0.022512</acceleration>
          <wrench>-0.025415 0.015261 0.033241 0 -0 0</wrench>
        </link>
        <link name='link_4'>
          <pose>-0.46888 -0.001082 1.02405 -1.82726 0.016586 -1.57283</pose>
          <velocity>-0.000807 -0.000197 0.000104 8e-05 -0.005866 0.000423</velocity>
          <acceleration>-0.003323 0.007726 0.009221 -0.010934 0.027161 0.035993</acceleration>
          <wrench>-0.006872 0.015979 0.019071 0 -0 0</wrench>
        </link>
        <link name='link_5'>
          <pose>-1.06861 -0.002471 1.18127 1.79443 1.49595 0.220989</pose>
          <velocity>-0.001728 -0.000463 -0.00342 5.1e-05 -0.016792 0.000245</velocity>
          <acceleration>-0.002832 -0.000285 -0.000199 -0.031074 -0.024956 0.02885</acceleration>
          <wrench>-0.00093 -9.4e-05 -6.5e-05 0 -0 0</wrench>
        </link>
        <link name='link_6'>
          <pose>-1.06861 -0.002471 1.18127 -0.072173 -0.019805 1.52432</pose>
          <velocity>-0.001728 -0.000463 -0.00342 8.1e-05 -0.016778 8.3e-05</velocity>
          <acceleration>-0.002039 3.6e-05 -0.000781 -0.000184 -0.001785 0.000419</acceleration>
          <wrench>-0.000827 1.5e-05 -0.000316 0 -0 0</wrench>
        </link>
        <link name='right_inner_finger'>
          <pose>-1.04932 0.069262 0.962331 3.12174 0.072159 3.09369</pose>
          <velocity>0.00194 -0.000445 -0.003092 5e-05 -0.016776 8e-05</velocity>
          <acceleration>-0.001369 0.000249 -0.001261 -0.000183 -0.001275 0.000217</acceleration>
          <wrench>-0.000274 5e-05 -0.000252 0 -0 0</wrench>
        </link>
        <link name='right_inner_knuckle'>
          <pose>-1.05456 0.013234 0.997614 3.12174 0.072159 3.09369</pose>
          <velocity>0.001352 -0.000447 -0.003184 4.7e-05 -0.016776 8e-05</velocity>
          <acceleration>-0.001603 0.00018 -0.001109 -0.000183 -0.001261 0.000198</acceleration>
          <wrench>-0.00016 1.8e-05 -0.000111 0 -0 0</wrench>
        </link>
        <link name='right_outer_knuckle'>
          <pose>-1.05421 0.031006 1.00447 3.12174 0.072159 3.09369</pose>
          <velocity>0.001236 -0.000447 -0.003176 5.4e-05 -0.016777 8.1e-05</velocity>
          <acceleration>-0.001711 0.000135 -0.000999 -0.000189 -0.001463 0.000258</acceleration>
          <wrench>-0.000342 2.7e-05 -0.0002 0 -0 0</wrench>
        </link>
      </model>
      <model name='table_red'>
        <pose>-1.0063 -0.006913 0 0 -0 0</pose>
        <scale>1 1 1</scale>
        <link name='link'>
          <pose>-1.0063 -0.006913 0 0 -0 0</pose>
          <velocity>0 0 0 0 -0 0</velocity>
          <acceleration>0 0 0 0 -0 0</acceleration>
          <wrench>0 0 0 0 -0 0</wrench>
        </link>
      </model>
      <light name='sun'>
        <pose>0 0 10 0 -0 0</pose>
      </light>
    </state>
    <model name='table_red'>
      <link name='link'>
        <self_collide>0</self_collide>
        <enable_wind>0</enable_wind>
        <kinematic>0</kinematic>
        <pose>0 0 0 0 -0 0</pose>
        <visual name='visual'>
          <geometry>
            <mesh>
              <uri>model://cafe_table/meshes/cafe_table.dae</uri>
            </mesh>
          </geometry>
          <material>
            <shader type='pixel'/>
          </material>
          <pose>0 0 0 0 -0 0</pose>
          <transparency>0</transparency>
          <cast_shadows>1</cast_shadows>
        </visual>
        <collision name='surface'>
          <laser_retro>0</laser_retro>
          <max_contacts>10</max_contacts>
          <pose>0 0 0.755 0 -0 0</pose>
          <geometry>
            <box>
              <size>0.913 0.913 0.04</size>
            </box>
          </geometry>
          <surface>
            <friction>
              <ode>
                <mu>1</mu>
                <mu2>1</mu2>
                <fdir1>0 0 0</fdir1>
                <slip1>0</slip1>
                <slip2>0</slip2>
              </ode>
              <torsional>
                <coefficient>1</coefficient>
                <patch_radius>0</patch_radius>
                <surface_radius>0</surface_radius>
                <use_patch_radius>1</use_patch_radius>
                <ode>
                  <slip>0</slip>
                </ode>
              </torsional>
            </friction>
            <bounce>
              <restitution_coefficient>0</restitution_coefficient>
              <threshold>1e+06</threshold>
            </bounce>
            <contact>
              <collide_without_contact>0</collide_without_contact>
              <collide_without_contact_bitmask>1</collide_without_contact_bitmask>
              <collide_bitmask>1</collide_bitmask>
              <ode>
                <soft_cfm>0</soft_cfm>
                <soft_erp>0.2</soft_erp>
                <kp>1e+13</kp>
                <kd>1</kd>
                <max_vel>0.01</max_vel>
                <min_depth>0</min_depth>
              </ode>
              <bullet>
                <split_impulse>1</split_impulse>
                <split_impulse_penetration_threshold>-0.01</split_impulse_penetration_threshold>
                <soft_cfm>0</soft_cfm>
                <soft_erp>0.2</soft_erp>
                <kp>1e+13</kp>
                <kd>1</kd>
              </bullet>
            </contact>
          </surface>
        </collision>
        <collision name='column'>
          <laser_retro>0</laser_retro>
          <max_contacts>10</max_contacts>
          <pose>0 0 0.37 0 -0 0</pose>
          <geometry>
            <box>
              <size>0.042 0.042 0.74</size>
            </box>
          </geometry>
          <surface>
            <friction>
              <ode>
                <mu>1</mu>
                <mu2>1</mu2>
                <fdir1>0 0 0</fdir1>
                <slip1>0</slip1>
                <slip2>0</slip2>
              </ode>
              <torsional>
                <coefficient>1</coefficient>
                <patch_radius>0</patch_radius>
                <surface_radius>0</surface_radius>
                <use_patch_radius>1</use_patch_radius>
                <ode>
                  <slip>0</slip>
                </ode>
              </torsional>
            </friction>
            <bounce>
              <restitution_coefficient>0</restitution_coefficient>
              <threshold>1e+06</threshold>
            </bounce>
            <contact>
              <collide_without_contact>0</collide_without_contact>
              <collide_without_contact_bitmask>1</collide_without_contact_bitmask>
              <collide_bitmask>1</collide_bitmask>
              <ode>
                <soft_cfm>0</soft_cfm>
                <soft_erp>0.2</soft_erp>
                <kp>1e+13</kp>
                <kd>1</kd>
                <max_vel>0.01</max_vel>
                <min_depth>0</min_depth>
              </ode>
              <bullet>
                <split_impulse>1</split_impulse>
                <split_impulse_penetration_threshold>-0.01</split_impulse_penetration_threshold>
                <soft_cfm>0</soft_cfm>
                <soft_erp>0.2</soft_erp>
                <kp>1e+13</kp>
                <kd>1</kd>
              </bullet>
            </contact>
          </surface>
        </collision>
        <collision name='base'>
          <laser_retro>0</laser_retro>
          <max_contacts>10</max_contacts>
          <pose>0 0 0.02 0 -0 0</pose>
          <geometry>
            <box>
              <size>0.56 0.56 0.04</size>
            </box>
          </geometry>
          <surface>
            <friction>
              <ode>
                <mu>1</mu>
                <mu2>1</mu2>
                <fdir1>0 0 0</fdir1>
                <slip1>0</slip1>
                <slip2>0</slip2>
              </ode>
              <torsional>
                <coefficient>1</coefficient>
                <patch_radius>0</patch_radius>
                <surface_radius>0</surface_radius>
                <use_patch_radius>1</use_patch_radius>
                <ode>
                  <slip>0</slip>
                </ode>
              </torsional>
            </friction>
            <bounce>
              <restitution_coefficient>0</restitution_coefficient>
              <threshold>1e+06</threshold>
            </bounce>
            <contact>
              <collide_without_contact>0</collide_without_contact>
              <collide_without_contact_bitmask>1</collide_without_contact_bitmask>
              <collide_bitmask>1</collide_bitmask>
              <ode>
                <soft_cfm>0</soft_cfm>
                <soft_erp>0.2</soft_erp>
                <kp>1e+13</kp>
                <kd>1</kd>
                <max_vel>0.01</max_vel>
                <min_depth>0</min_depth>
              </ode>
              <bullet>
                <split_impulse>1</split_impulse>
                <split_impulse_penetration_threshold>-0.01</split_impulse_penetration_threshold>
                <soft_cfm>0</soft_cfm>
                <soft_erp>0.2</soft_erp>
                <kp>1e+13</kp>
                <kd>1</kd>
              </bullet>
            </contact>
          </surface>
        </collision>
      </link>
      <static>1</static>
      <allow_auto_disable>1</allow_auto_disable>
      <pose>-1.0063 -0.006913 0 0 -0 0</pose>
    </model>
    <model name='blue_table'>
      <link name='link'>
        <self_collide>0</self_collide>
        <enable_wind>0</enable_wind>
        <kinematic>0</kinematic>
        <pose>0 0 0 0 -0 0</pose>
        <visual name='visual'>
          <geometry>
            <mesh>
              <uri>model://cafe_table/meshes/cafe_table.dae</uri>
            </mesh>
          </geometry>
          <material>
            <shader type='pixel'/>
          </material>
          <pose>0 0 0 0 -0 0</pose>
          <transparency>0</transparency>
          <cast_shadows>1</cast_shadows>
        </visual>
        <collision name='surface'>
          <laser_retro>0</laser_retro>
          <max_contacts>10</max_contacts>
          <pose>0 0 0.755 0 -0 0</pose>
          <geometry>
            <box>
              <size>0.913 0.913 0.04</size>
            </box>
          </geometry>
          <surface>
            <friction>
              <ode>
                <mu>1</mu>
                <mu2>1</mu2>
                <fdir1>0 0 0</fdir1>
                <slip1>0</slip1>
                <slip2>0</slip2>
              </ode>
              <torsional>
                <coefficient>1</coefficient>
                <patch_radius>0</patch_radius>
                <surface_radius>0</surface_radius>
                <use_patch_radius>1</use_patch_radius>
                <ode>
                  <slip>0</slip>
                </ode>
              </torsional>
            </friction>
            <bounce>
              <restitution_coefficient>0</restitution_coefficient>
              <threshold>1e+06</threshold>
            </bounce>
            <contact>
              <collide_without_contact>0</collide_without_contact>
              <collide_without_contact_bitmask>1</collide_without_contact_bitmask>
              <collide_bitmask>1</collide_bitmask>
              <ode>
                <soft_cfm>0</soft_cfm>
                <soft_erp>0.2</soft_erp>
                <kp>1e+13</kp>
                <kd>1</kd>
                <max_vel>0.01</max_vel>
                <min_depth>0</min_depth>
              </ode>
              <bullet>
                <split_impulse>1</split_impulse>
                <split_impulse_penetration_threshold>-0.01</split_impulse_penetration_threshold>
                <soft_cfm>0</soft_cfm>
                <soft_erp>0.2</soft_erp>
                <kp>1e+13</kp>
                <kd>1</kd>
              </bullet>
            </contact>
          </surface>
        </collision>
        <collision name='column'>
          <laser_retro>0</laser_retro>
          <max_contacts>10</max_contacts>
          <pose>0 0 0.37 0 -0 0</pose>
          <geometry>
            <box>
              <size>0.042 0.042 0.74</size>
            </box>
          </geometry>
          <surface>
            <friction>
              <ode>
                <mu>1</mu>
                <mu2>1</mu2>
                <fdir1>0 0 0</fdir1>
                <slip1>0</slip1>
                <slip2>0</slip2>
              </ode>
              <torsional>
                <coefficient>1</coefficient>
                <patch_radius>0</patch_radius>
                <surface_radius>0</surface_radius>
                <use_patch_radius>1</use_patch_radius>
                <ode>
                  <slip>0</slip>
                </ode>
              </torsional>
            </friction>
            <bounce>
              <restitution_coefficient>0</restitution_coefficient>
              <threshold>1e+06</threshold>
            </bounce>
            <contact>
              <collide_without_contact>0</collide_without_contact>
              <collide_without_contact_bitmask>1</collide_without_contact_bitmask>
              <collide_bitmask>1</collide_bitmask>
              <ode>
                <soft_cfm>0</soft_cfm>
                <soft_erp>0.2</soft_erp>
                <kp>1e+13</kp>
                <kd>1</kd>
                <max_vel>0.01</max_vel>
                <min_depth>0</min_depth>
              </ode>
              <bullet>
                <split_impulse>1</split_impulse>
                <split_impulse_penetration_threshold>-0.01</split_impulse_penetration_threshold>
                <soft_cfm>0</soft_cfm>
                <soft_erp>0.2</soft_erp>
                <kp>1e+13</kp>
                <kd>1</kd>
              </bullet>
            </contact>
          </surface>
        </collision>
        <collision name='base'>
          <laser_retro>0</laser_retro>
          <max_contacts>10</max_contacts>
          <pose>0 0 0.02 0 -0 0</pose>
          <geometry>
            <box>
              <size>0.56 0.56 0.04</size>
            </box>
          </geometry>
          <surface>
            <friction>
              <ode>
                <mu>1</mu>
                <mu2>1</mu2>
                <fdir1>0 0 0</fdir1>
                <slip1>0</slip1>
                <slip2>0</slip2>
              </ode>
              <torsional>
                <coefficient>1</coefficient>
                <patch_radius>0</patch_radius>
                <surface_radius>0</surface_radius>
                <use_patch_radius>1</use_patch_radius>
                <ode>
                  <slip>0</slip>
                </ode>
              </torsional>
            </friction>
            <bounce>
              <restitution_coefficient>0</restitution_coefficient>
              <threshold>1e+06</threshold>
            </bounce>
            <contact>
              <collide_without_contact>0</collide_without_contact>
              <collide_without_contact_bitmask>1</collide_without_contact_bitmask>
              <collide_bitmask>1</collide_bitmask>
              <ode>
                <soft_cfm>0</soft_cfm>
                <soft_erp>0.2</soft_erp>
                <kp>1e+13</kp>
                <kd>1</kd>
                <max_vel>0.01</max_vel>
                <min_depth>0</min_depth>
              </ode>
              <bullet>
                <split_impulse>1</split_impulse>
                <split_impulse_penetration_threshold>-0.01</split_impulse_penetration_threshold>
                <soft_cfm>0</soft_cfm>
                <soft_erp>0.2</soft_erp>
                <kp>1e+13</kp>
                <kd>1</kd>
              </bullet>
            </contact>
          </surface>
        </collision>
      </link>
      <static>1</static>
      <allow_auto_disable>1</allow_auto_disable>
      <pose>1.00143 0.003949 0 0 -0 0</pose>
    </model>
    <gui fullscreen='0'>
      <camera name='user_camera'>
        <pose>-0.785435 -5.24106 1.30286 -0 0.217795 1.5442</pose>
        <view_controller>orbit</view_controller>
        <projection_type>perspective</projection_type>
      </camera>
    </gui>
  </world>
</sdf>
